<?xml version="1.0"?>
    <robot xmlns:xacro="http://wiki.ros.org/xacro" name="wheel">
    <link type="text/css" rel="stylesheet" id="dark-mode-custom-link"/>
    <link type="text/css" rel="stylesheet" id="dark-mode-general-link"/>
    <style lang="en" type="text/css" id="dark-mode-custom-style"/>
    <style lang="en" type="text/css" id="dark-mode-native-style"/>
    <style lang="en" type="text/css" id="dark-mode-native-sheet"/>
    <!-- <xacro:include filename="$(find msr_robot)/urdf/utils/utils.urdf.xacro"/> -->
    
    <!--  WHEEL XACRO  -->
    <xacro:macro name="rover_wheel" params="prefix parent *origin">
        <!-- TIRE  -->
        <joint name="${prefix}wheel_joint" type="continuous">
            <xacro:insert_block name="origin"/>
            <parent link="${parent}"/>
            <child link="${prefix}wheel_link"/>
            <axis xyz="0 0 1" rpy="0 0 0"/>
            <limit effort="5000" velocity="100"/>
            <dynamics damping="0.05" friction="0.1"/>
        </joint>
        
        <link name="${prefix}wheel_link">
            <inertial>
                <origin xyz="0 0 0" rpy="0 0 0"/>
                <mass value="10.0"/>
                <inertia ixx="0.02975" ixy="0" ixz="0" iyy="0.03087" iyz="0" izz="0.00191"/>
            </inertial>
            <visual>
                <origin xyz="0 0 0" rpy="0 0 0"/>
                <geometry>
                <mesh filename="file:///home/msdelta/modsimspace/src/msr_world/meshes/Cylinder.dae" scale="1.0 1.0 1.0"/>
                </geometry>
            </visual>
            <collision>
                <origin xyz="0 0 0" rpy="0 0 0"/>
                <geometry>
                <cylinder length="0.3" radius="0.3"/>
                </geometry>
            </collision>
        </link>
        
        <!--  Transmission is important to link the joints and the controller (see summit_xl_control/config/summit_xl_control.yaml) -->
        <transmission name="${prefix}_wheel_joint_trans">
            <type>transmission_interface/SimpleTransmission</type>
            <joint name="${prefix}wheel_joint">
                <hardwareInterface>hardware_interface/VelocityJointInterface</hardwareInterface>
            </joint>
            <actuator name="${prefix}wheel_joint_motor">
                <mechanicalReduction>1</mechanicalReduction>
            </actuator>
        </transmission>
        
        <gazebo reference="${prefix}wheel_link">
            <mu1>5</mu1>
            <mu2>5</mu2>
            <!-- kp>2.75e6</kp>
                <kd>8.25e1</kd>
                <fdir1>0 0 0</fdir1>
                <maxContacts>4</maxContacts -->
        </gazebo>
    </xacro:macro>
    </robot>
