<?xml version="1.0"?>
<!-- created with Phobos 1.0.1 "Capricious Choutengan" -->
  <robot name="rover" xmlns:xacro="http://wiki.ros.org/xacro">

    <!-- root link: -->
    <link name="base_link">
      <inertial>
        <origin xyz="-0.13251 0 0.1675" rpy="0 0 0"/>
        <mass value="16.0"/>
        <inertia ixx="1.32771" ixy="0" ixz="0" iyy="4.12376" iyz="0" izz="0.20041"/>
      </inertial>
      <visual name="chassis">
        <origin xyz="0 0 0" rpy="0 0 0"/>
        <geometry>
          <mesh filename="file:///home/msdelta/modsimspace/src/msr_world/meshes/Cube.011.dae" scale="0.65 0.5 0.065"/>
        </geometry>
      </visual>
      <collision name="chassis">
        <origin xyz="-0.13251 0 0.1675" rpy="0 0 0"/>
        <geometry>
          <box size="2.0 1.3 0.4"/>
        </geometry>
      </collision>
    </link>

    <link name="back_left_wheel">
      <inertial>
        <origin xyz="0 0 0" rpy="0 0 0"/>
        <mass value="0.7"/>
        <inertia ixx="0.00065" ixy="0" ixz="0" iyy="0.00056" iyz="0" izz="0.00021"/>
      </inertial>
      <visual name="blw_body">
        <origin xyz="0 0 0" rpy="0 0 0"/>
        <geometry>
          <mesh filename="file:///home/msdelta/modsimspace/src/msr_world/meshes/Cylinder.002.dae" scale="0.2 0.2 0.15"/>
        </geometry>
      </visual>
      <collision name="blw_body">
        <origin xyz="0 0 0" rpy="0 0 0"/>
        <geometry>
          <cylinder radius="0.2" length="0.3"/>
        </geometry>
      </collision>
    </link>

    <link name="back_right_wheel">
      <inertial>
        <origin xyz="0 0 0" rpy="0 0 0"/>
        <mass value="0.7"/>
        <inertia ixx="0.01225" ixy="0" ixz="0" iyy="0.014" iyz="0" izz="0.01225"/>
      </inertial>
      <visual name="brw_body">
        <origin xyz="0 0 0" rpy="0 0 0"/>
        <geometry>
          <mesh filename="file:///home/msdelta/modsimspace/src/msr_world/meshes/Cylinder.005.dae" scale="0.2 0.2 0.15"/>
        </geometry>
      </visual>
      <collision name="brw_body">
        <origin xyz="0 0 0" rpy="0 0 0"/>
        <geometry>
          <cylinder radius="0.2" length="0.3"/>
        </geometry>
      </collision>
    </link>

    <link name="base_box_link">
      <inertial>
        <origin xyz="0 0 0" rpy="0 0 0"/>
        <mass value="1.0"/>
        <inertia ixx="0.18833" ixy="0" ixz="0" iyy="0.18833" iyz="0" izz="0.375"/>
      </inertial>
      <visual name="box_base">
        <origin xyz="0 0 0" rpy="0 0 0"/>
        <geometry>
          <box size="1.5 1.5 0.1"/>
        </geometry>
      </visual>
      <collision name="box_base">
        <origin xyz="0 0 0" rpy="0 0 0"/>
        <geometry>
          <box size="1.5 1.5 0.1"/>
        </geometry>
      </collision>
    </link>

    <link name="front_left_wheel">
      <inertial>
        <origin xyz="0 0 0" rpy="0 0 0"/>
        <mass value="0.7"/>
        <inertia ixx="0.01225" ixy="0" ixz="0" iyy="0.014" iyz="0" izz="0.01225"/>
      </inertial>
      <visual name="flw_body">
        <origin xyz="0 0 0" rpy="0 0 0"/>
        <geometry>
          <mesh filename="file:///home/msdelta/modsimspace/src/msr_world/meshes/Cylinder.dae" scale="0.2 0.2 0.15"/>
        </geometry>
      </visual>
      <collision name="flw_body">
        <origin xyz="0 0 0" rpy="0 0 0"/>
        <geometry>
          <cylinder radius="0.2" length="0.3"/>
        </geometry>
      </collision>
    </link>

    <link name="front_right_wheel">
      <inertial>
        <origin xyz="0 0 0" rpy="0 0 0"/>
        <mass value="0.7"/>
        <inertia ixx="0.01225" ixy="0" ixz="0" iyy="0.014" iyz="0" izz="0.01225"/>
      </inertial>
      <visual name="frw_body">
        <origin xyz="0 0 0" rpy="0 0 0"/>
        <geometry>
          <mesh filename="file:///home/msdelta/modsimspace/src/msr_world/meshes/Cylinder.001.dae" scale="0.2 0.2 0.15"/>
        </geometry>
      </visual>
      <collision name="frw_body">
        <origin xyz="0 0 0" rpy="0 0 0"/>
        <geometry>
          <cylinder radius="0.2" length="0.3"/>
        </geometry>
      </collision>
    </link>

    <link name="mid_left_wheel">
      <inertial>
        <origin xyz="0 0 0" rpy="0 0 0"/>
        <mass value="0.7"/>
        <inertia ixx="0.01225" ixy="0" ixz="0" iyy="0.014" iyz="0" izz="0.01225"/>
      </inertial>
      <visual name="mlw_body">
        <origin xyz="0 0 0" rpy="0 0 0"/>
        <geometry>
          <mesh filename="file:///home/msdelta/modsimspace/src/msr_world/meshes/Cylinder.003.dae" scale="0.2 0.2 0.15"/>
        </geometry>
      </visual>
      <collision name="mlw_body">
        <origin xyz="0 0 0" rpy="0 0 0"/>
        <geometry>
          <cylinder radius="0.2" length="0.3"/>
        </geometry>
      </collision>
    </link>

    <link name="mid_right_wheel">
      <inertial>
        <origin xyz="0 0 0" rpy="0 0 0"/>
        <mass value="0.7"/>
        <inertia ixx="0.01225" ixy="0" ixz="0" iyy="0.014" iyz="0" izz="0.01225"/>
      </inertial>
      <visual name="mrw_body">
        <origin xyz="0 0 0" rpy="0 0 0"/>
        <geometry>
          <mesh filename="file:///home/msdelta/modsimspace/src/msr_world/meshes/Cylinder.004.dae" scale="0.2 0.2 0.15"/>
        </geometry>
      </visual>
      <collision name="mrw_body">
        <origin xyz="0 0 0" rpy="0 0 0"/>
        <geometry>
          <cylinder radius="0.2" length="0.3"/>
        </geometry>
      </collision>
    </link>

    <link name="wall_b">
      <inertial>
        <origin xyz="0 0 0" rpy="0 0 0"/>
        <mass value="1.0"/>
        <inertia ixx="0.21271" ixy="0" ixz="0" iyy="0.02604" iyz="0" izz="0.18833"/>
      </inertial>
      <visual name="wb">
        <origin xyz="0 0 0" rpy="0 0 0"/>
        <geometry>
          <box size="0.1 1.5 0.55"/>
        </geometry>
      </visual>
      <collision name="wb">
        <origin xyz="0 0 0" rpy="0 0 0"/>
        <geometry>
          <box size="0.1 1.5 0.55"/>
        </geometry>
      </collision>
    </link>

    <link name="wall_f">
      <inertial>
        <origin xyz="0 0 0" rpy="0 0 0"/>
        <mass value="1.0"/>
        <inertia ixx="0.14833" ixy="0" ixz="0" iyy="0.00833" iyz="0" izz="0.14167"/>
      </inertial>
      <visual name="wf">
        <origin xyz="0 0 0" rpy="0 0 0"/>
        <geometry>
          <box size="0.1 1.3 0.3"/>
        </geometry>
      </visual>
      <collision name="wf">
        <origin xyz="0 0 0" rpy="0 0 0"/>
        <geometry>
          <box size="0.1 1.3 0.3"/>
        </geometry>
      </collision>
    </link>

    <link name="wall_l">
      <inertial>
        <origin xyz="0 0 0" rpy="0 0 0"/>
        <mass value="1.0"/>
        <inertia ixx="0.02604" ixy="0" ixz="0" iyy="0.18854" iyz="0" izz="0.16417"/>
      </inertial>
      <visual name="wl">
        <origin xyz="0 0 0" rpy="0 0 0"/>
        <geometry>
          <box size="0.1 1.4 0.55"/>
        </geometry>
      </visual>
      <collision name="wl">
        <origin xyz="0 0 0" rpy="0 0 0"/>
        <geometry>
          <box size="0.1 1.4 0.55"/>
        </geometry>
      </collision>
    </link>

    <link name="wall_r">
      <inertial>
        <origin xyz="0 0 0" rpy="0 0 0"/>
        <mass value="1.0"/>
        <inertia ixx="0.02604" ixy="0" ixz="0" iyy="0.18854" iyz="0" izz="0.16417"/>
      </inertial>
      <visual name="wr">
        <origin xyz="0 0 0" rpy="0 0 0"/>
        <geometry>
          <box size="0.1 1.4 0.55"/>
        </geometry>
      </visual>
      <collision name="wr">
        <origin xyz="0 0 0" rpy="0 0 0"/>
        <geometry>
          <box size="0.1 1.4 0.55"/>
        </geometry>
      </collision>
    </link>

    <joint name="base_box_joint" type="fixed">
      <origin xyz="-0.6 0 0.3925" rpy="0 0 0"/>
      <parent link="base_link"/>
      <child link="base_box_link"/>
    </joint>

    <!-- <xacro:include filename="/home/msdelta/modsimspace/src/msr_world/urdf/rover_wheel.urdf.xacro"/>

    <xacro:rover_wheel prefix="blw_" parent="base_link">
      <origin xyz="-1.1 -0.8 -0.4575"/>
    </xacro:rover_wheel>

    <xacro:rover_wheel prefix="brw_" parent="base_link">
      <origin xyz="-1.1 0.8 -0.4575"/>
    </xacro:rover_wheel>

    <xacro:rover_wheel prefix="flw_" parent="base_link">
      <origin xyz="1.0 -0.8 -0.4575"/>
    </xacro:rover_wheel>

    <xacro:rover_wheel prefix="frw_" parent="base_link">
      <origin xyz="1.0 0.8 -0.4575"/>
    </xacro:rover_wheel>

    <xacro:rover_wheel prefix="mlw_" parent="base_link">
      <origin xyz="-0.3 -0.8 -0.4575"/>
    </xacro:rover_wheel>

    <xacro:rover_wheel prefix="mrw_" parent="base_link">
      <origin xyz="-0.3 0.8 -0.4575"/>
    </xacro:rover_wheel> -->

    <joint name="blw_joint" type="continuous">
      <origin xyz="-1.1 -0.8 -0.4575" rpy="1.5708 0 0"/>
      <parent link="base_link"/>
      <child link="back_left_wheel"/>
      <axis xyz="0 0 1.0"/>
      <limit effort="100.0" velocity="20.0"/>
    </joint>

    <joint name="brw_joint" type="continuous">
      <origin xyz="-1.1 0.8 -0.4575" rpy="1.5708 0 0"/>
      <parent link="base_link"/>
      <child link="back_right_wheel"/>
      <axis xyz="0 0 1.0"/>
      <limit effort="100.0" velocity="20.0"/>
    </joint>

    <joint name="flw_joint" type="continuous">
      <origin xyz="1.0 -0.8 -0.4575" rpy="1.5708 0 0"/>
      <parent link="base_link"/>
      <child link="front_left_wheel"/>
      <axis xyz="0 0 1.0"/>
      <limit effort="100.0" velocity="20.0"/>
    </joint>

    <joint name="frw_joint" type="continuous">
      <origin xyz="1.0 0.8 -0.4575" rpy="1.5708 0 0"/>
      <parent link="base_link"/>
      <child link="front_right_wheel"/>
      <axis xyz="0 0 1.0"/>
      <limit effort="100.0" velocity="20.0"/>
    </joint>

    <joint name="mlw_joint" type="continuous">
      <origin xyz="-0.3 -0.8 -0.4575" rpy="1.5708 0 0"/>
      <parent link="base_link"/>
      <child link="mid_left_wheel"/>
      <axis xyz="0 0 1.0"/>
      <limit effort="100.0" velocity="20.0"/>
    </joint>

    <joint name="mrw_joint" type="continuous">
      <origin xyz="-0.3 0.8 -0.4575" rpy="1.5708 0 0"/>
      <parent link="base_link"/>
      <child link="mid_right_wheel"/>
      <axis xyz="0 0 1.0"/>
      <limit effort="100.0" velocity="20.0"/>
    </joint>

    <joint name="wall_b_joint" type="fixed">
      <origin xyz="-0.7 0 0.325" rpy="0 0 0"/>
      <parent link="base_box_link"/>
      <child link="wall_b"/>
    </joint>

    <joint name="wall_f_joint" type="fixed">
      <origin xyz="0.7 0 0.2" rpy="0 0 0"/>
      <parent link="base_box_link"/>
      <child link="wall_f"/>
    </joint>

    <joint name="wall_l_joint" type="fixed">
      <origin xyz="0.05 -0.7 0.325" rpy="0 0 1.5708"/>
      <parent link="base_box_link"/>
      <child link="wall_l"/>
    </joint>

    <joint name="wall_r_joint" type="fixed">
      <origin xyz="0.05 0.7 0.325" rpy="0 0 1.5708"/>
      <parent link="base_box_link"/>
      <child link="wall_r"/>
    </joint>

    <!-- Frame de odom -->
    <!-- <joint name="odom_joint" type="fixed">
      <parent link="odom"/>
      <child link="base_link"/>
      <origin xyz="0 0 0" rpy="0 0 0"/>
    </joint> -->

    <!-- Frame de map -->
    <!-- <joint name="map_joint" type="fixed">
      <parent link="map"/>
      <child link="odom"/>
      <origin xyz="0 0 0" rpy="0 0 0"/>
    </joint> -->

    <!-- ******** SENSORS ******** -->
    <xacro:include filename="/home/msdelta/modsimspace/src/msr_world/sensors/rob_sensors.urdf.xacro"/>

    <xacro:sensor_camera_generic frame_prefix="front_" parent="base_link" node_name="camera_node" topic_prefix="~/" horizontal_fov="110" vertical_fov="70" video_width="1920" video_height="1080" video_fps="30">
      <origin xyz="1 0 0" rpy="0 0 0"/>
    </xacro:sensor_camera_generic>

    <xacro:sensor_imu prefix="imu" parent="base_link">
      <origin xyz="0 0 0" rpy="0 0 0"/>
    </xacro:sensor_imu>

  </robot>
